<?xml version="1.0"?>
<robot name="my_robot">

    <!--  All links and joints are declared here -->
    <link name="base_link">
    </link>

   <link name="chassis">
     <visual>
       <geometry>
         <box size="0.4 0.4 0.1"/>
       </geometry>
     </visual>
   </link>


   <joint name="chassis_joint" type="fixed">
     <parent link="base_link"/>
     <child link="chassis"/>
   </joint>
   
   <material name="blue">
     <color rgba="0 0 0.8 1"/>
   </material>

   <!--right front wheel-->
   <link name="front_wheel_right">
     <visual>
       <geometry>
         <cylinder length="0.04" radius="0.06"/>
       </geometry>
       <material name="blue"/>
     </visual>
   </link>

   <joint name="front_wheel_right_joint" type="continuous">
     <parent link="chassis"/>
     <child link="front_wheel_right"/>
     <origin xyz="0.2 -0.225 0" rpy="1.5707 0 0"/>
     <axis xyz="0 0 -1"/>
   </joint>


</robot>

